Workbook

Sheet 假设
A1: Tesla (TSLA) DCF — 核心假设
A2: 单位：十亿美元（另注明除外）。蓝色=手工输入；黄色底=关键假设；黑色=公式；绿色=跨页引用。
A3: 市场数据
A4: 估值基准日 | B4: =DATE(2026,10,10) -> 46305
A5: 股价 (US$) | B5: 382.7
A6: 稀释后股数 (十亿股) | B6: 3.95
A7: 情景（1=悲观 2=基准 3=乐观） | B7: 2
A8: WACC
A9: 无风险利率 | B9: 0.042
A10: 股权风险溢价 | B10: 0.05
A11: Beta | B11: 1.5
A12: 税前债务成本 | B12: 0.055
A13: 目标负债率 D/(D+E) | B13: 0.01
A14: 预测期
A15: 有效税率 | B15: 0.18
A16: 永续增长率 g | B16: 0.03
A17: 折旧摊销 / 收入 | B17: 0.055
A18: 永续期资本开支 / 折旧 | B18: 1.15
A19: 增量营运资本 / 增量收入 | B19: 0
A20: 资产负债表 (2026-06-30)
A21: 现金及短期投资 | B21: 43.52
A22: 有息负债及融资租赁 | B22: 9.34
A24: 计算得出
A25: 股权成本 Ke | B25: =$B$9+$B$11*$B$10 -> 0.117
A26: 税后债务成本 Kd | B26: =$B$12*(1-$B$15) -> 0.0451
A27: WACC | B27: =(1-$B$13)*$B$25+$B$13*$B$26 -> 0.116281
A28: 2026 年剩余期间（年） | B28: =(DATE(2026,12,31)-$B$4)/365 -> 0.22465753
A29: 净现金 | B29: =$B$21-$B$22 -> 34.18
A30: 市值 | B30: =$B$5*$B$6 -> 1511.665
A32: 情景假设（2026E–2035E） | C32: 2026E | D32: 2027E | E32: 2028E | F32: 2029E | G32: 2030E | H32: 2031E | I32: 2032E | J32: 2033E | K32: 2034E | L32: 2035E
A33: 收入增长率
A34: 悲观 | B34: 1 | C34: 0.1 | D34: 0.06 | E34: 0.07 | F34: 0.07 | G34: 0.06 | H34: 0.05 | I34: 0.05 | J34: 0.04 | K34: 0.04 | L34: 0.03
A35: 基准 | B35: 2 | C35: 0.128 | D35: 0.18 | E35: 0.2 | F35: 0.18 | G35: 0.16 | H35: 0.14 | I35: 0.12 | J35: 0.1 | K35: 0.08 | L35: 0.06
A36: 乐观 | B36: 3 | C36: 0.13 | D36: 0.28 | E36: 0.32 | F36: 0.3 | G36: 0.26 | H36: 0.22 | I36: 0.18 | J36: 0.14 | K36: 0.1 | L36: 0.08
A37: EBIT 利润率
A38: 悲观 | B38: 1 | C38: 0.03 | D38: 0.04 | E38: 0.05 | F38: 0.06 | G38: 0.07 | H38: 0.075 | I38: 0.08 | J38: 0.085 | K38: 0.09 | L38: 0.09
A39: 基准 | B39: 2 | C39: 0.035 | D39: 0.055 | E39: 0.075 | F39: 0.095 | G39: 0.115 | H39: 0.13 | I39: 0.145 | J39: 0.155 | K39: 0.16 | L39: 0.16
A40: 乐观 | B40: 3 | C40: 0.035 | D40: 0.07 | E40: 0.11 | F40: 0.15 | G40: 0.18 | H40: 0.2 | I40: 0.21 | J40: 0.22 | K40: 0.22 | L40: 0.22
A41: 资本开支 / 收入
A42: 悲观 | B42: 1 | C42: 0.233 | D42: 0.15 | E42: 0.11 | F42: 0.09 | G42: 0.08 | H42: 0.075 | I42: 0.07 | J42: 0.065 | K42: 0.065 | L42: =$B$17*$B$18 -> 0.06325
...

Sheet DCF
A1: Tesla DCF 预测（十亿美元）
A2: ="当前情景："&CHOOSE(假设!$B$7,"悲观","基准","乐观") -> 当前情景：基准
A4: 年度 | B4: 2024A | C4: 2025A | D4: 2026E | E4: 2027E | F4: 2028E | G4: 2029E | H4: 2030E | I4: 2031E | J4: 2032E | K4: 2033E | L4: 2034E | M4: 2035E
A5: 收入增长率 | C5: =C6/B6-1 -> -0.029276282 | D5: =CHOOSE(假设!$B$7,假设!C34,假设!C35,假设!C36) -> 0.128 | E5: =CHOOSE(假设!$B$7,假设!D34,假设!D35,假设!D36) -> 0.18 | F5: =CHOOSE(假设!$B$7,假设!E34,假设!E35,假设!E36) -> 0.2 | G5: =CHOOSE(假设!$B$7,假设!F34,假设!F35,假设!F36) -> 0.18 | H5: =CHOOSE(假设!$B$7,假设!G34,假设!G35,假设!G36) -> 0.16 | I5: =CHOOSE(假设!$B$7,假设!H34,假设!H35,假设!H36) -> 0.14 | J5: =CHOOSE(假设!$B$7,假设!I34,假设!I35,假设!I36) -> 0.12 | K5: =CHOOSE(假设!$B$7,假设!J34,假设!J35,假设!J36) -> 0.1 | ... M5: =CHOOSE(假设!$B$7,假设!L34,假设!L35,假设!L36) -> 0.06
A6: 营业收入 | B6: 97.69 | C6: 94.83 | D6: =C6*(1+D5) -> 106.96824 | E6: =D6*(1+E5) -> 126.22252 | F6: =E6*(1+F5) -> 151.46703 | G6: =F6*(1+G5) -> 178.73109 | H6: =G6*(1+H5) -> 207.32807 | I6: =H6*(1+I5) -> 236.354 | J6: =I6*(1+J5) -> 264.71648 | K6: =J6*(1+K5) -> 291.18812 | ... M6: =L6*(1+M5) -> 333.35216
A7: EBIT 利润率 | B7: =B8/B6 -> 0.072474153 | C7: =C8/C6 -> 0.045977011 | D7: =CHOOSE(假设!$B$7,假设!C38,假设!C39,假设!C40) -> 0.035 | E7: =CHOOSE(假设!$B$7,假设!D38,假设!D39,假设!D40) -> 0.055 | F7: =CHOOSE(假设!$B$7,假设!E38,假设!E39,假设!E40) -> 0.075 | G7: =CHOOSE(假设!$B$7,假设!F38,假设!F39,假设!F40) -> 0.095 | H7: =CHOOSE(假设!$B$7,假设!G38,假设!G39,假设!G40) -> 0.115 | I7: =CHOOSE(假设!$B$7,假设!H38,假设!H39,假设!H40) -> 0.13 | J7: =CHOOSE(假设!$B$7,假设!I38,假设!I39,假设!I40) -> 0.145 | K7: =CHOOSE(假设!$B$7,假设!J38,假设!J39,假设!J40) -> 0.155 | ... M7: =CHOOSE(假设!$B$7,假设!L38,假设!L39,假设!L40) -> 0.16
A8: EBIT（GAAP，含股权激励费用） | B8: 7.08 | C8: 4.36 | D8: =D6*D7 -> 3.7438884 | E8: =E6*E7 -> 6.9422388 | F8: =F6*F7 -> 11.360027 | G8: =G6*G7 -> 16.979454 | H8: =H6*H7 -> 23.842728 | I8: =I6*I7 -> 30.72602 | J8: =J6*J7 -> 38.383889 | K8: =K6*K7 -> 45.134159 | ... M8: =M6*M7 -> 53.336346
A9: 所得税 | D9: =-MAX(D8,0)*假设!$B$15 -> -0.67389991 | E9: =-MAX(E8,0)*假设!$B$15 -> -1.249603 | F9: =-MAX(F8,0)*假设!$B$15 -> -2.0448049 | G9: =-MAX(G8,0)*假设!$B$15 -> -3.0563017 | H9: =-MAX(H8,0)*假设!$B$15 -> -4.291691 | I9: =-MAX(I8,0)*假设!$B$15 -> -5.5306835 | J9: =-MAX(J8,0)*假设!$B$15 -> -6.9091 | K9: =-MAX(K8,0)*假设!$B$15 -> -8.1241487 | ... M9: =-MAX(M8,0)*假设!$B$15 -> -9.6005424
A10: NOPAT | D10: =D8+D9 -> 3.0699885 | E10: =E8+E9 -> 5.6926358 | F10: =F8+F9 -> 9.3152222 | G10: =G8+G9 -> 13.923152 | H10: =H8+H9 -> 19.551037 | I10: =I8+I9 -> 25.195336 | J10: =J8+J9 -> 31.474789 | K10: =K8+K9 -> 37.010011 | ... M10: =M8+M9 -> 43.735804
A11: 折旧摊销 | B11: 5.37 | C11: 5 | D11: =D6*假设!$B$17 -> 5.8832532 | E11: =E6*假设!$B$17 -> 6.9422388 | F11: =F6*假设!$B$17 -> 8.3306865 | G11: =G6*假设!$B$17 -> 9.8302101 | H11: =H6*假设!$B$17 -> 11.403044 | I11: =I6*假设!$B$17 -> 12.99947 | J11: =J6*假设!$B$17 -> 14.559406 | K11: =K6*假设!$B$17 -> 16.015347 | ... M11: =M6*假设!$B$17 -> 18.334369
A12: 资本开支 / 收入 | B12: =-B13/B6 -> 0.11608148 | C12: =-C13/C6 -> 0.089950438 | D12: =CHOOSE(假设!$B$7,假设!C42,假设!C43,假设!C44) -> 0.233 | E12: =CHOOSE(假设!$B$7,假设!D42,假设!D43,假设!D44) -> 0.17 | F12: =CHOOSE(假设!$B$7,假设!E42,假设!E43,假设!E44) -> 0.13 | G12: =CHOOSE(假设!$B$7,假设!F42,假设!F43,假设!F44) -> 0.1 | H12: =CHOOSE(假设!$B$7,假设!G42,假设!G43,假设!G44) -> 0.085 | I12: =CHOOSE(假设!$B$7,假设!H42,假设!H43,假设!H44) -> 0.075 | J12: =CHOOSE(假设!$B$7,假设!I42,假设!I43,假设!I44) -> 0.07 | K12: =CHOOSE(假设!$B$7,假设!J42,假设!J43,假设!J44) -> 0.065 | ... M12: =CHOOSE(假设!$B$7,假设!L42,假设!L43,假设!L44) -> 0.06325
A13: 资本开支 | B13: -11.34 | C13: -8.53 | D13: =-D6*D12 -> -24.9236 | E13: =-E6*E12 -> -21.457829 | F13: =-F6*F12 -> -19.690714 | G13: =-G6*G12 -> -17.873109 | H13: =-H6*H12 -> -17.622886 | I13: =-I6*I12 -> -17.72655 | J13: =-J6*J12 -> -18.530153 | K13: =-K6*K12 -> -18.927228 | ... M13: =-M6*M12 -> -21.084524
A14: 增量营运资本 | D14: =-(D6-C6)*假设!$B$19 -> 0 | E14: =-(E6-D6)*假设!$B$19 -> 0 | F14: =-(F6-E6)*假设!$B$19 -> 0 | G14: =-(G6-F6)*假设!$B$19 -> 0 | H14: =-(H6-G6)*假设!$B$19 -> 0 | I14: =-(I6-H6)*假设!$B$19 -> 0 | J14: =-(J6-I6)*假设!$B$19 -> 0 | K14: =-(K6-J6)*假设!$B$19 -> 0 | ... M14: =-(M6-L6)*假设!$B$19 -> 0
A15: 自由现金流 FCFF | D15: =D10+D11+D13+D14 -> -15.970358 | E15: =E10+E11+E13+E14 -> -8.8229544 | F15: =F10+F11+F13+F14 -> -2.0448049 | G15: =G10+G11+G13+G14 -> 5.880253 | H15: =H10+H11+H13+H14 -> 13.331195 | I15: =I10+I11+I13+I14 -> 20.468256 | J15: =J10+J11+J13+J14 -> 27.504042 | K15: =K10+K11+K13+K14 -> 34.098129 | ... M15: =M10+M11+M13+M14 -> 40.985649
A17: 折现期（年） | D17: =假设!$B$28 -> 0.22465753 | E17: =D17+1 -> 1.2246575 | F17: =E17+1 -> 2.2246575 | G17: =F17+1 -> 3.2246575 | H17: =G17+1 -> 4.2246575 | I17: =H17+1 -> 5.2246575 | J17: =I17+1 -> 6.2246575 | K17: =J17+1 -> 7.2246575 | L17: =K17+1 -> 8.2246575 | M17: =L17+1 -> 9.2246575
A18: 折现因子 | D18: =1/(1+假设!$B$27)^D17 -> 0.97558995 | E18: =1/(1+假设!$B$27)^E17 -> 0.87396448 | F18: =1/(1+假设!$B$27)^F17 -> 0.78292516 | G18: =1/(1+假设!$B$27)^G17 -> 0.70136924 | H18: =1/(1+假设!$B$27)^H17 -> 0.62830886 | I18: =1/(1+假设!$B$27)^I17 -> 0.56285905 | J18: =1/(1+假设!$B$27)^J17 -> 0.50422703 | K18: =1/(1+假设!$B$27)^K17 -> 0.4517026 | ... M18: =1/(1+假设!$B$27)^M17 -> 0.36249792
A19: FCFF 现值 | D19: =D15*D18*假设!$B$28 -> -3.5002814 | E19: =E15*E18 -> -7.7109487 | F19: =F15*F18 -> -1.6009292 | G19: =G15*G18 -> 4.1242286 | H19: =H15*H18 -> 8.3761078 | I19: =I15*I18 -> 11.520743 | J19: =J15*J18 -> 13.868281 | K19: =K15*K18 -> 15.402214 | L19: =L15*L18 -> 15.423363 | M19: =M15*M18 -> 14.857212
A20: 注：2026E 现金流仅计入基准日后剩余部分；EBIT 已扣除股权激励费用（视为真实成本）
A21: 参考：经营现金流 | B21: 14.92 | C21: 14.75
A22: 参考：公司口径 FCF | B22: 3.58 | C22: 6.22
A25: 估值汇总
A26: 预测期 FCFF 现值合计 | B26: =SUM(D19:M19) -> 70.759991
A27: 终值（Gordon，2035E 末） | B27: =M15*(1+假设!$B$16)/(假设!$B$27-假设!$B$16) -> 489.27595
A28: 终值现值 | B28: =B27*M18 -> 177.36151
A29: 企业价值 EV | B29: =B26+B28 -> 248.12151
A30: 加：净现金 | B30: =假设!$B$29 -> 34.18
A31: 股权价值 | B31: =B29+B30 -> 282.30151
A32: 每股价值（US$） | B32: =B31/假设!$B$6 -> 71.468736
A33: 当前股价（US$） | B33: =假设!$B$5 -> 382.7
A34: 上行/下行空间 | B34: =B32/B33-1 -> -0.81325128
A35: 终值占 EV 比重 | B35: =B28/B29 -> 0.71481718
A36: 反推：市价隐含 2035E FCFF | B36: =(假设!$B$30-假设!$B$29-B26)/M18*(假设!$B$27-假设!$B$16)/(1+假设!$B$16) -> 325.07355
A37: 市价隐含 FCFF / 模型 2035E FCFF | B37: =B36/M15 -> 7.9313994
A38: 反推：在模型 WACC 与 g 下，要支撑当前市值，2035E 需要达到的自由现金流

Sheet 敏感性
A1: 每股价值（US$）敏感性：WACC × 永续增长率（当前情景）
A2: 每格独立重算 FCFF 折现与终值；切换 假设 页情景后自动更新
A4: WACC ↓ / g → | B4: 0.02 | C4: 0.025 | D4: 0.03 | E4: 0.035 | F4: 0.04
A5: 0.08 | B5: =(SUMPRODUCT(DCF!$D$15:$M$15,1/(1+$A5)^DCF!$D$17:$M$17)-DCF!$D$15*(1-假设!$B$28)/(1+$A5)^DCF!$D$17+DCF!$M$15*(1+B$4)/($A5-B$4)/(1+$A5)^DCF!$M$17+假设!$B$29)/假设!$B$6 -> 118.57458 | C5: =(SUMPRODUCT(DCF!$D$15:$M$15,1/(1+$A5)^DCF!$D$17:$M$17)-DCF!$D$15*(1-假设!$B$28)/(1+$A5)^DCF!$D$17+DCF!$M$15*(1+C$4)/($A5-C$4)/(1+$A5)^DCF!$M$17+假设!$B$29)/假设!$B$6 -> 126.92276 | D5: =(SUMPRODUCT(DCF!$D$15:$M$15,1/(1+$A5)^DCF!$D$17:$M$17)-DCF!$D$15*(1-假设!$B$28)/(1+$A5)^DCF!$D$17+DCF!$M$15*(1+D$4)/($A5-D$4)/(1+$A5)^DCF!$M$17+假设!$B$29)/假设!$B$6 -> 136.94058 | E5: =(SUMPRODUCT(DCF!$D$15:$M$15,1/(1+$A5)^DCF!$D$17:$M$17)-DCF!$D$15*(1-假设!$B$28)/(1+$A5)^DCF!$D$17+DCF!$M$15*(1+E$4)/($A5-E$4)/(1+$A5)^DCF!$M$17+假设!$B$29)/假设!$B$6 -> 149.18458 | F5: =(SUMPRODUCT(DCF!$D$15:$M$15,1/(1+$A5)^DCF!$D$17:$M$17)-DCF!$D$15*(1-假设!$B$28)/(1+$A5)^DCF!$D$17+DCF!$M$15*(1+F$4)/($A5-F$4)/(1+$A5)^DCF!$M$17+假设!$B$29)/假设!$B$6 -> 164.48958
A6: 0.09 | B6: =(SUMPRODUCT(DCF!$D$15:$M$15,1/(1+$A6)^DCF!$D$17:$M$17)-DCF!$D$15*(1-假设!$B$28)/(1+$A6)^DCF!$D$17+DCF!$M$15*(1+B$4)/($A6-B$4)/(1+$A6)^DCF!$M$17+假设!$B$29)/假设!$B$6 -> 98.519931 | C6: =(SUMPRODUCT(DCF!$D$15:$M$15,1/(1+$A6)^DCF!$D$17:$M$17)-DCF!$D$15*(1-假设!$B$28)/(1+$A6)^DCF!$D$17+DCF!$M$15*(1+C$4)/($A6-C$4)/(1+$A6)^DCF!$M$17+假设!$B$29)/假设!$B$6 -> 104.13265 | D6: =(SUMPRODUCT(DCF!$D$15:$M$15,1/(1+$A6)^DCF!$D$17:$M$17)-DCF!$D$15*(1-假设!$B$28)/(1+$A6)^DCF!$D$17+DCF!$M$15*(1+D$4)/($A6-D$4)/(1+$A6)^DCF!$M$17+假设!$B$29)/假设!$B$6 -> 110.68082 | E6: =(SUMPRODUCT(DCF!$D$15:$M$15,1/(1+$A6)^DCF!$D$17:$M$17)-DCF!$D$15*(1-假设!$B$28)/(1+$A6)^DCF!$D$17+DCF!$M$15*(1+E$4)/($A6-E$4)/(1+$A6)^DCF!$M$17+假设!$B$29)/假设!$B$6 -> 118.41957 | F6: =(SUMPRODUCT(DCF!$D$15:$M$15,1/(1+$A6)^DCF!$D$17:$M$17)-DCF!$D$15*(1-假设!$B$28)/(1+$A6)^DCF!$D$17+DCF!$M$15*(1+F$4)/($A6-F$4)/(1+$A6)^DCF!$M$17+假设!$B$29)/假设!$B$6 -> 127.70606
A7: 0.1 | B7: =(SUMPRODUCT(DCF!$D$15:$M$15,1/(1+$A7)^DCF!$D$17:$M$17)-DCF!$D$15*(1-假设!$B$28)/(1+$A7)^DCF!$D$17+DCF!$M$15*(1+B$4)/($A7-B$4)/(1+$A7)^DCF!$M$17+假设!$B$29)/假设!$B$6 -> 83.672387 | C7: =(SUMPRODUCT(DCF!$D$15:$M$15,1/(1+$A7)^DCF!$D$17:$M$17)-DCF!$D$15*(1-假设!$B$28)/(1+$A7)^DCF!$D$17+DCF!$M$15*(1+C$4)/($A7-C$4)/(1+$A7)^DCF!$M$17+假设!$B$29)/假设!$B$6 -> 87.620711 | D7: =(SUMPRODUCT(DCF!$D$15:$M$15,1/(1+$A7)^DCF!$D$17:$M$17)-DCF!$D$15*(1-假设!$B$28)/(1+$A7)^DCF!$D$17+DCF!$M$15*(1+D$4)/($A7-D$4)/(1+$A7)^DCF!$M$17+假设!$B$29)/假设!$B$6 -> 92.133082 | E7: =(SUMPRODUCT(DCF!$D$15:$M$15,1/(1+$A7)^DCF!$D$17:$M$17)-DCF!$D$15*(1-假设!$B$28)/(1+$A7)^DCF!$D$17+DCF!$M$15*(1+E$4)/($A7-E$4)/(1+$A7)^DCF!$M$17+假设!$B$29)/假设!$B$6 -> 97.339663 | F7: =(SUMPRODUCT(DCF!$D$15:$M$15,1/(1+$A7)^DCF!$D$17:$M$17)-DCF!$D$15*(1-假设!$B$28)/(1+$A7)^DCF!$D$17+DCF!$M$15*(1+F$4)/($A7-F$4)/(1+$A7)^DCF!$M$17+假设!$B$29)/假设!$B$6 -> 103.41401
A8: 0.11 | B8: =(SUMPRODUCT(DCF!$D$15:$M$15,1/(1+$A8)^DCF!$D$17:$M$17)-DCF!$D$15*(1-假设!$B$28)/(1+$A8)^DCF!$D$17+DCF!$M$15*(1+B$4)/($A8-B$4)/(1+$A8)^DCF!$M$17+假设!$B$29)/假设!$B$6 -> 72.284997 | C8: =(SUMPRODUCT(DCF!$D$15:$M$15,1/(1+$A8)^DCF!$D$17:$M$17)-DCF!$D$15*(1-假设!$B$28)/(1+$A8)^DCF!$D$17+DCF!$M$15*(1+C$4)/($A8-C$4)/(1+$A8)^DCF!$M$17+假设!$B$29)/假设!$B$6 -> 75.159596 | D8: =(SUMPRODUCT(DCF!$D$15:$M$15,1/(1+$A8)^DCF!$D$17:$M$17)-DCF!$D$15*(1-假设!$B$28)/(1+$A8)^DCF!$D$17+DCF!$M$15*(1+D$4)/($A8-D$4)/(1+$A8)^DCF!$M$17+假设!$B$29)/假设!$B$6 -> 78.393521 | E8: =(SUMPRODUCT(DCF!$D$15:$M$15,1/(1+$A8)^DCF!$D$17:$M$17)-DCF!$D$15*(1-假设!$B$28)/(1+$A8)^DCF!$D$17+DCF!$M$15*(1+E$4)/($A8-E$4)/(1+$A8)^DCF!$M$17+假设!$B$29)/假设!$B$6 -> 82.058635 | F8: =(SUMPRODUCT(DCF!$D$15:$M$15,1/(1+$A8)^DCF!$D$17:$M$17)-DCF!$D$15*(1-假设!$B$28)/(1+$A8)^DCF!$D$17+DCF!$M$15*(1+F$4)/($A8-F$4)/(1+$A8)^DCF!$M$17+假设!$B$29)/假设!$B$6 -> 86.247336
A9: 0.12 | B9: =(SUMPRODUCT(DCF!$D$15:$M$15,1/(1+$A9)^DCF!$D$17:$M$17)-DCF!$D$15*(1-假设!$B$28)/(1+$A9)^DCF!$D$17+DCF!$M$15*(1+B$4)/($A9-B$4)/(1+$A9)^DCF!$M$17+假设!$B$29)/假设!$B$6 -> 63.310371 | C9: =(SUMPRODUCT(DCF!$D$15:$M$15,1/(1+$A9)^DCF!$D$17:$M$17)-DCF!$D$15*(1-假设!$B$28)/(1+$A9)^DCF!$D$17+DCF!$M$15*(1+C$4)/($A9-C$4)/(1+$A9)^DCF!$M$17+假设!$B$29)/假设!$B$6 -> 65.460575 | D9: =(SUMPRODUCT(DCF!$D$15:$M$15,1/(1+$A9)^DCF!$D$17:$M$17)-DCF!$D$15*(1-假设!$B$28)/(1+$A9)^DCF!$D$17+DCF!$M$15*(1+D$4)/($A9-D$4)/(1+$A9)^DCF!$M$17+假设!$B$29)/假设!$B$6 -> 67.849691 | E9: =(SUMPRODUCT(DCF!$D$15:$M$15,1/(1+$A9)^DCF!$D$17:$M$17)-DCF!$D$15*(1-假设!$B$28)/(1+$A9)^DCF!$D$17+DCF!$M$15*(1+E$4)/($A9-E$4)/(1+$A9)^DCF!$M$17+假设!$B$29)/假设!$B$6 -> 70.519879 | F9: =(SUMPRODUCT(DCF!$D$15:$M$15,1/(1+$A9)^DCF!$D$17:$M$17)-DCF!$D$15*(1-假设!$B$28)/(1+$A9)^DCF!$D$17+DCF!$M$15*(1+F$4)/($A9-F$4)/(1+$A9)^DCF!$M$17+假设!$B$29)/假设!$B$6 -> 73.523841
A10: 0.13 | B10: =(SUMPRODUCT(DCF!$D$15:$M$15,1/(1+$A10)^DCF!$D$17:$M$17)-DCF!$D$15*(1-假设!$B$28)/(1+$A10)^DCF!$D$17+DCF!$M$15*(1+B$4)/($A10-B$4)/(1+$A10)^DCF!$M$17+假设!$B$29)/假设!$B$6 -> 56.082635 | C10: =(SUMPRODUCT(DCF!$D$15:$M$15,1/(1+$A10)^DCF!$D$17:$M$17)-DCF!$D$15*(1-假设!$B$28)/(1+$A10)^DCF!$D$17+DCF!$M$15*(1+C$4)/($A10-C$4)/(1+$A10)^DCF!$M$17+假设!$B$29)/假设!$B$6 -> 57.726517 | D10: =(SUMPRODUCT(DCF!$D$15:$M$15,1/(1+$A10)^DCF!$D$17:$M$17)-DCF!$D$15*(1-假设!$B$28)/(1+$A10)^DCF!$D$17+DCF!$M$15*(1+D$4)/($A10-D$4)/(1+$A10)^DCF!$M$17+假设!$B$29)/假设!$B$6 -> 59.534788 | E10: =(SUMPRODUCT(DCF!$D$15:$M$15,1/(1+$A10)^DCF!$D$17:$M$17)-DCF!$D$15*(1-假设!$B$28)/(1+$A10)^DCF!$D$17+DCF!$M$15*(1+E$4)/($A10-E$4)/(1+$A10)^DCF!$M$17+假设!$B$29)/假设!$B$6 -> 61.533402 | F10: =(SUMPRODUCT(DCF!$D$15:$M$15,1/(1+$A10)^DCF!$D$17:$M$17)-DCF!$D$15*(1-假设!$B$28)/(1+$A10)^DCF!$D$17+DCF!$M$15*(1+F$4)/($A10-F$4)/(1+$A10)^DCF!$M$17+假设!$B$29)/假设!$B$6 -> 63.754085
A12: 当前股价 | B12: =假设!$B$5 -> 382.7
A13: 模型 WACC | B13: =假设!$B$27 -> 0.116281

Sheet 来源与说明
A1: 数据来源
A2: Q2 2026：收入 282.4 亿（+26%），营业利润 3.98 亿（利润率 1.4%），经营现金流 47.0 亿，资本开支 57.9 亿，FCF −10.9 亿，现金及投资 435.2 亿，全年资本开支指引约 250 亿 — https://electrek.co/2026/07/22/tesla-tsla-q2-2026-financial-results/ ；https://www.sec.gov/Archives/edgar/data/0001318605/000162828026049213/exhibit991.htm
A3: Q1 2026：收入 223.9 亿（+16%），营业利润 9.41 亿 — https://www.tikr.com/blog/tesla-q1-2026-earnings-revenue-up-16-eps-up-52-but-free-cash-flow-turns-negative
A4: FY2025：收入 948 亿，营业利润 43.6 亿，经营现金流 147.5 亿，资本开支 85.3 亿，FCF 62.2 亿 — https://www.just-auto.com/?p=189439 ；https://last10k.com/sec-filings/tsla/0001628280-26-003837.htm
A5: 债务（2026-06-30，10-Q 附注 8）— https://www.sec.gov/Archives/edgar/data/0001318605/000162828026049270/tsla-20260630.htm
A6: 股本 3,755,723,871 股（2026-04-16）— https://www.sec.gov/Archives/edgar/data/0001318605/000162828026026673/tsla-20260331.htm
A7: 2026 收入一致预期 1,069 亿（Visible Alpha）— https://www.spglobal.com/market-intelligence/en/news-insights/research/2026/07/tesla-postq-revenue-beat-overshadowed-by-margin-pressure
A8: 股价 $382.70（2026-10-09 收盘）— https://www.cnbc.com/quotes/TSLA
A10: 主要局限
A11: 1. 模型按“汽车 + 储能 + 服务”整体现金流建模，未单独为 Robotaxi、Optimus、AI 业务建立分部估值；乐观情景只是粗略反映这些期权价值。
A12: 2. 2024 年折旧摊销为估算；稀释股数含 CEO 限制性股票的估计。
A13: 3. 股权激励视为真实费用（EBIT 已扣除），未在现金流中加回。
... A15: 5. Q3 2026 财报预计 10 月下旬发布，届时应更新。
